2022-08-11 13:13:20,102:ERROR:neat:gen-mut-model failed, see the traceback below
Traceback (most recent call last):
  File "/Users/ralhazmy/Documents/NEAT/NEAT/neat/cli/cli.py", line 133, in main
    cmd(args)
  File "/Users/ralhazmy/Documents/NEAT/NEAT/neat/cli/commands/gen_mut_model.py", line 53, in execute
    compute_mut_runner(arguments.reference, arguments.mutations, arguments.bed, arguments.outcounts, arguments.show_trinuc,
  File "/Users/ralhazmy/Documents/NEAT/NEAT/neat/gen_mut_model/runner.py", line 565, in compute_mut_runner
    if not mutations.is_file(mutations):
AttributeError: 'str' object has no attribute 'is_file'
