2022-08-16 04:17:07,786:ERROR:neat:gen-mut-model failed, see the traceback below
Traceback (most recent call last):
  File "/Users/ralhazmy/Documents/NEAT/NEAT/neat/cli/cli.py", line 133, in main
    cmd(args)
  File "/Users/ralhazmy/Documents/NEAT/NEAT/neat/cli/commands/gen_mut_model.py", line 53, in execute
    compute_mut_runner(arguments.reference, arguments.mutations, arguments.bed, arguments.outcounts, arguments.show_trinuc,
  File "/Users/ralhazmy/Documents/NEAT/NEAT/neat/gen_mut_model/runner.py", line 582, in compute_mut_runner
    vcf_header = extract_header(mutations)
  File "/Users/ralhazmy/Documents/NEAT/NEAT/neat/gen_mut_model/runner.py", line 42, in extract_header
    for line in f:
TypeError: '_GeneratorContextManager' object is not iterable
